<?xml version="1.0" ?>
<!-- =================================================================================== -->
<!-- |    This document was autogenerated by xacro from src/libertech_humanoid/libertech_humanoid_description/urdf/hand.xacro | -->
<!-- |    EDITING THIS FILE BY HAND IS NOT RECOMMENDED                                 | -->
<!-- =================================================================================== -->
<robot name="liberhand_left">
  <link name="world"/>
  <joint name="world_to_hand_left_palm_fixed" type="fixed">
    <origin rpy="0.0 0.0 0.0" xyz="0.0 0.0 0.0"/>
    <parent link="world"/>
    <child link="hand_left_palm"/>
  </joint>
  <link name="hand_left_palm">
    <inertial>
      <origin rpy="0 0 0" xyz="0 0 0"/>
      <mass value="0.91778"/>
      <inertia ixx="0.0018592" ixy="6.239E-05" ixz="-6.688E-05" iyy="0.0015814" iyz="3.163E-05" izz="0.00064901"/>
    </inertial>
    <visual>
      <origin rpy="0 0 0" xyz="0 0 0"/>
      <geometry>
        <mesh filename="../meshes/visual/palm.STL" scale="1 -1 1"/>
      </geometry>
      <material name="hand_gray">
        <color rgba="0.2 0.2 0.2 1"/>
      </material>
    </visual>
    <collision>
      <origin rpy="0 0 0" xyz="0 0 0"/>
      <geometry>
        <mesh filename="../meshes/visual/palm.STL" scale="1 -1 1"/>
      </geometry>
    </collision>
  </link>
  <link name="hand_left_f11">
    <inertial>
      <origin rpy="0 0 0" xyz="0 0.00069742 -0.0093798"/>
      <mass value="0.0033015"/>
      <inertia ixx="2E-07" ixy="0" ixz="0" iyy="3.1E-07" iyz="1E-08" izz="1.4E-07"/>
    </inertial>
    <visual>
      <origin rpy="0 0 0" xyz="0 0 0"/>
      <geometry>
        <mesh filename="../meshes/visual/f11.STL"/>
      </geometry>
      <material name="hand_white">
        <color rgba="0.913725 0.913725 0.847059 1"/>
      </material>
    </visual>
    <collision>
      <origin rpy="0 0 0" xyz="0 0 0"/>
      <geometry>
        <mesh filename="../meshes/visual/f11.STL"/>
      </geometry>
    </collision>
  </link>
  <joint name="hand_left_f11_joint" type="revolute">
    <origin rpy="1.5708 -0.02618 1.5708" xyz="-0.022466 -0.027654 0.043657"/>
    <parent link="hand_left_palm"/>
    <child link="hand_left_f11"/>
    <axis xyz="0 0 1"/>
    <limit effort="10" lower="-0.4" upper="0.4" velocity="3.14"/>
    <dynamics damping="1.0" friction="0.01"/>
  </joint>
  <link name="hand_left_f12">
    <inertial>
      <origin rpy="0 0 0" xyz="0.026032 -0.0074611 2.268E-05"/>
      <mass value="0.058465"/>
      <inertia ixx="4.34E-06" ixy="-4.9E-06" ixz="5.3E-07" iyy="1.396E-05" iyz="-2.1E-07" izz="1.633E-05"/>
    </inertial>
    <visual>
      <origin rpy="0 0 0" xyz="0 0 0"/>
      <geometry>
        <mesh filename="../meshes/visual/f12.STL"/>
      </geometry>
      <material name="hand_white">
        <color rgba="0.913725 0.913725 0.847059 1"/>
      </material>
    </visual>
    <collision>
      <origin rpy="0 0 0" xyz="0 0 0"/>
      <geometry>
        <mesh filename="../meshes/visual/f12.STL"/>
      </geometry>
    </collision>
  </link>
  <joint name="hand_left_f12_joint" type="revolute">
    <origin rpy="1.5708 0 1.5708" xyz="0 0 0"/>
    <parent link="hand_left_f11"/>
    <child link="hand_left_f12"/>
    <axis xyz="0 0 1"/>
    <limit effort="10" lower="0" upper="2.09" velocity="3.14"/>
    <dynamics damping="1.0" friction="0.01"/>
  </joint>
  <link name="hand_left_f13">
    <inertial>
      <origin rpy="0 0 0" xyz="0.0090975 -0.0015069 0.0013415"/>
      <mass value="0.014574"/>
      <inertia ixx="9.3E-07" ixy="-3.2E-07" ixz="-1.8E-07" iyy="2.04E-06" iyz="6E-08" izz="1.81E-06"/>
    </inertial>
    <visual>
      <origin rpy="0 0 0" xyz="0 0 0"/>
      <geometry>
        <mesh filename="../meshes/visual/f13.STL"/>
      </geometry>
      <material name="hand_white">
        <color rgba="0.913725 0.913725 0.847059 1"/>
      </material>
    </visual>
    <collision>
      <origin rpy="0 0 0" xyz="0 0 0"/>
      <geometry>
        <mesh filename="../meshes/visual/f13.STL"/>
      </geometry>
    </collision>
  </link>
  <joint name="hand_left_f13_joint" type="revolute">
    <origin rpy="0 0 0" xyz="0.048883 -0.018383 0"/>
    <parent link="hand_left_f12"/>
    <child link="hand_left_f13"/>
    <axis xyz="0 0 1"/>
    <limit effort="10" lower="0" upper="1.744" velocity="3.14"/>
    <dynamics damping="1.0" friction="0.01"/>
  </joint>
  <link name="hand_left_f14">
    <inertial>
      <origin rpy="0 0 0" xyz="0.007749 -0.0041898 -0.00072552"/>
      <mass value="0.0055228"/>
      <inertia ixx="2.3E-07" ixy="-1.5E-07" ixz="2E-08" iyy="4E-07" iyz="-1E-08" izz="5E-07"/>
    </inertial>
    <visual>
      <origin rpy="0 0 0" xyz="0 0 0"/>
      <geometry>
        <mesh filename="../meshes/visual/f14.STL"/>
      </geometry>
      <material name="hand_white">
        <color rgba="0.913725 0.913725 0.847059 1"/>
      </material>
    </visual>
    <collision>
      <origin rpy="0 0 0" xyz="0 0 0"/>
      <geometry>
        <mesh filename="../meshes/visual/f14.STL"/>
      </geometry>
    </collision>
  </link>
  <joint name="hand_left_f14_joint" type="revolute">
    <origin rpy="0 0 0" xyz="0.0284 -0.0092477 0"/>
    <parent link="hand_left_f13"/>
    <child link="hand_left_f14"/>
    <axis xyz="0 0 1"/>
    <limit effort="10" lower="0" upper="1.744" velocity="3.14"/>
    <dynamics damping="1.0" friction="0.01"/>
  </joint>
  <link name="hand_left_f14_end">
        </link>
  <joint name="hand_left_f14_end_joint" type="fixed">
    <origin rpy="0 0 0" xyz="0.019695 -0.0034802 0"/>
    <parent link="hand_left_f14"/>
    <child link="hand_left_f14_end"/>
    <axis xyz="0 0 0"/>
  </joint>
  <link name="hand_left_f21">
    <inertial>
      <origin rpy="0 0 0" xyz="0 0.00069742 -0.0093798"/>
      <mass value="0.0033015"/>
      <inertia ixx="2E-07" ixy="0" ixz="0" iyy="3.1E-07" iyz="1E-08" izz="1.4E-07"/>
    </inertial>
    <visual>
      <origin rpy="0 0 0" xyz="0 0 0"/>
      <geometry>
        <mesh filename="../meshes/visual/f21.STL"/>
      </geometry>
      <material name="hand_white">
        <color rgba="0.913725 0.913725 0.847059 1"/>
      </material>
    </visual>
    <collision>
      <origin rpy="0 0 0" xyz="0 0 0"/>
      <geometry>
        <mesh filename="../meshes/visual/f21.STL"/>
      </geometry>
    </collision>
  </link>
  <joint name="hand_left_f21_joint" type="revolute">
    <origin rpy="1.5708 0 1.5708" xyz="-0.022466 -0.0022583 0.053546"/>
    <parent link="hand_left_palm"/>
    <child link="hand_left_f21"/>
    <axis xyz="0 0 1"/>
    <limit effort="10" lower="-0.4" upper="0.4" velocity="3.14"/>
    <dynamics damping="1.0" friction="0.01"/>
  </joint>
  <link name="hand_left_f22">
    <inertial>
      <origin rpy="0 0 0" xyz="0.026032 -0.0074611 2.268E-05"/>
      <mass value="0.058465"/>
      <inertia ixx="4.34E-06" ixy="-4.9E-06" ixz="5.3E-07" iyy="1.396E-05" iyz="-2.1E-07" izz="1.633E-05"/>
    </inertial>
    <visual>
      <origin rpy="0 0 0" xyz="0 0 0"/>
      <geometry>
        <mesh filename="../meshes/visual/f22.STL"/>
      </geometry>
      <material name="hand_white">
        <color rgba="0.913725 0.913725 0.847059 1"/>
      </material>
    </visual>
    <collision>
      <origin rpy="0 0 0" xyz="0 0 0"/>
      <geometry>
        <mesh filename="../meshes/visual/f22.STL"/>
      </geometry>
    </collision>
  </link>
  <joint name="hand_left_f22_joint" type="revolute">
    <origin rpy="1.5708 0 1.5708" xyz="0 0 0"/>
    <parent link="hand_left_f21"/>
    <child link="hand_left_f22"/>
    <axis xyz="0 0 1"/>
    <limit effort="10" lower="0" upper="2.09" velocity="3.14"/>
    <dynamics damping="1.0" friction="0.01"/>
  </joint>
  <link name="hand_left_f23">
    <inertial>
      <origin rpy="0 0 0" xyz="0.0090975 -0.0015069 0.0013415"/>
      <mass value="0.014574"/>
      <inertia ixx="9.3E-07" ixy="-3.2E-07" ixz="-1.8E-07" iyy="2.04E-06" iyz="6E-08" izz="1.81E-06"/>
    </inertial>
    <visual>
      <origin rpy="0 0 0" xyz="0 0 0"/>
      <geometry>
        <mesh filename="../meshes/visual/f23.STL"/>
      </geometry>
      <material name="hand_white">
        <color rgba="0.913725 0.913725 0.847059 1"/>
      </material>
    </visual>
    <collision>
      <origin rpy="0 0 0" xyz="0 0 0"/>
      <geometry>
        <mesh filename="../meshes/visual/f23.STL"/>
      </geometry>
    </collision>
  </link>
  <joint name="hand_left_f23_joint" type="revolute">
    <origin rpy="0 0 0" xyz="0.048883 -0.018383 0"/>
    <parent link="hand_left_f22"/>
    <child link="hand_left_f23"/>
    <axis xyz="0 0 1"/>
    <limit effort="10" lower="0" upper="1.744" velocity="3.14"/>
    <dynamics damping="1.0" friction="0.01"/>
  </joint>
  <link name="hand_left_f24">
    <inertial>
      <origin rpy="0 0 0" xyz="0.007749 -0.0041898 -0.00072552"/>
      <mass value="0.0055228"/>
      <inertia ixx="2.3E-07" ixy="-1.5E-07" ixz="2E-08" iyy="4E-07" iyz="-1E-08" izz="5E-07"/>
    </inertial>
    <visual>
      <origin rpy="0 0 0" xyz="0 0 0"/>
      <geometry>
        <mesh filename="../meshes/visual/f24.STL"/>
      </geometry>
      <material name="hand_white">
        <color rgba="0.913725 0.913725 0.847059 1"/>
      </material>
    </visual>
    <collision>
      <origin rpy="0 0 0" xyz="0 0 0"/>
      <geometry>
        <mesh filename="../meshes/visual/f24.STL"/>
      </geometry>
    </collision>
  </link>
  <joint name="hand_left_f24_joint" type="revolute">
    <origin rpy="0 0 0" xyz="0.0284 -0.0092477 0"/>
    <parent link="hand_left_f23"/>
    <child link="hand_left_f24"/>
    <axis xyz="0 0 1"/>
    <limit effort="10" lower="0" upper="1.744" velocity="3.14"/>
    <dynamics damping="1.0" friction="0.01"/>
  </joint>
  <link name="hand_left_f24_end">
        </link>
  <joint name="hand_left_f24_end_joint" type="fixed">
    <origin rpy="0 0 0" xyz="0.019695 -0.0034802 0"/>
    <parent link="hand_left_f24"/>
    <child link="hand_left_f24_end"/>
    <axis xyz="0 0 0"/>
  </joint>
  <link name="hand_left_f31">
    <inertial>
      <origin rpy="0 0 0" xyz="-6.964E-05 -0.00044078 -0.012759"/>
      <mass value="0.0085521"/>
      <inertia ixx="7.6E-07" ixy="0" ixz="0" iyy="7.6E-07" iyz="4E-08" izz="1.3E-07"/>
    </inertial>
    <visual>
      <origin rpy="0 0 0" xyz="0 0 0"/>
      <geometry>
        <mesh filename="../meshes/visual/f31.STL"/>
      </geometry>
      <material name="hand_white">
        <color rgba="0.913725 0.913725 0.847059 1"/>
      </material>
    </visual>
    <collision>
      <origin rpy="0 0 0" xyz="0 0 0"/>
      <geometry>
        <mesh filename="../meshes/visual/f31.STL"/>
      </geometry>
    </collision>
  </link>
  <joint name="hand_left_f31_joint" type="revolute">
    <origin rpy="1.5708 0 1.5708" xyz="-0.021466 0.017542 0.047798"/>
    <parent link="hand_left_palm"/>
    <child link="hand_left_f31"/>
    <axis xyz="0 0 1"/>
    <limit effort="10" lower="-0.4" upper="0.4" velocity="3.14"/>
    <dynamics damping="1.0" friction="0.01"/>
  </joint>
  <link name="hand_left_f32">
    <inertial>
      <origin rpy="0 0 0" xyz="0.025132 0.0031733 -8.727E-05"/>
      <mass value="0.01244"/>
      <inertia ixx="4.5E-07" ixy="-1.2E-07" ixz="0" iyy="2.29E-06" iyz="0" izz="2.41E-06"/>
    </inertial>
    <visual>
      <origin rpy="0 0 0" xyz="0 0 0"/>
      <geometry>
        <mesh filename="../meshes/visual/f32.STL"/>
      </geometry>
      <material name="hand_white">
        <color rgba="0.913725 0.913725 0.847059 1"/>
      </material>
    </visual>
    <collision>
      <origin rpy="0 0 0" xyz="0 0 0"/>
      <geometry>
        <mesh filename="../meshes/visual/f32.STL"/>
      </geometry>
    </collision>
  </link>
  <joint name="hand_left_f32_joint" type="revolute">
    <origin rpy="1.5708 0 1.5708" xyz="0 0 0"/>
    <parent link="hand_left_f31"/>
    <child link="hand_left_f32"/>
    <axis xyz="0 0 1"/>
    <limit effort="10" lower="0" upper="1.744" velocity="3.14"/>
    <dynamics damping="1.0" friction="0.01"/>
  </joint>
  <link name="hand_left_f33">
    <inertial>
      <origin rpy="0 0 0" xyz="0.010032 -0.00058707 -9.093E-05"/>
      <mass value="0.0071009"/>
      <inertia ixx="2.8E-07" ixy="-8E-08" ixz="0" iyy="6.9E-07" iyz="0" izz="7E-07"/>
    </inertial>
    <visual>
      <origin rpy="0 0 0" xyz="0 0 0"/>
      <geometry>
        <mesh filename="../meshes/visual/f33.STL"/>
      </geometry>
      <material name="hand_white">
        <color rgba="0.913725 0.913725 0.847059 1"/>
      </material>
    </visual>
    <collision>
      <origin rpy="0 0 0" xyz="0 0 0"/>
      <geometry>
        <mesh filename="../meshes/visual/f33.STL"/>
      </geometry>
    </collision>
  </link>
  <joint name="hand_left_f33_joint" type="revolute">
    <origin rpy="0 0 0" xyz="0.044995 0.00066781 0"/>
    <parent link="hand_left_f32"/>
    <child link="hand_left_f33"/>
    <axis xyz="0 0 1"/>
    <limit effort="10" lower="0" upper="1.744" velocity="3.14"/>
    <dynamics damping="1.0" friction="0.01"/>
  </joint>
  <link name="hand_left_f34">
    <inertial>
      <origin rpy="0 0 0" xyz="0.010482 -0.0030354 -1.03E-05"/>
      <mass value="0.0049513"/>
      <inertia ixx="1.3E-07" ixy="-6E-08" ixz="0" iyy="3.2E-07" iyz="0" izz="3.7E-07"/>
    </inertial>
    <visual>
      <origin rpy="0 0 0" xyz="0 0 0"/>
      <geometry>
        <mesh filename="../meshes/visual/f34.STL"/>
      </geometry>
      <material name="hand_white">
        <color rgba="0.913725 0.913725 0.847059 1"/>
      </material>
    </visual>
    <collision>
      <origin rpy="0 0 0" xyz="0 0 0"/>
      <geometry>
        <mesh filename="../meshes/visual/f34.STL"/>
      </geometry>
    </collision>
  </link>
  <joint name="hand_left_f34_joint" type="revolute">
    <origin rpy="0 0 0" xyz="0.024601 -0.0044465 0"/>
    <parent link="hand_left_f33"/>
    <child link="hand_left_f34"/>
    <axis xyz="0 0 1"/>
    <limit effort="10" lower="0" upper="1.744" velocity="3.14"/>
    <dynamics damping="1.0" friction="0.01"/>
  </joint>
  <link name="hand_left_f34_end">
        </link>
  <joint name="hand_left_f34_end_joint" type="fixed">
    <origin rpy="0 0 0" xyz="0.021134 0.0011803 0"/>
    <parent link="hand_left_f34"/>
    <child link="hand_left_f34_end"/>
    <axis xyz="0 0 0"/>
  </joint>
  <link name="hand_left_f41">
    <inertial>
      <origin rpy="0 0 0" xyz="-6.964E-05 -0.00044078 -0.012759"/>
      <mass value="0.0085521"/>
      <inertia ixx="7.6E-07" ixy="0" ixz="0" iyy="7.6E-07" iyz="4E-08" izz="1.3E-07"/>
    </inertial>
    <visual>
      <origin rpy="0 0 0" xyz="0 0 0"/>
      <geometry>
        <mesh filename="../meshes/visual/f41.STL"/>
      </geometry>
      <material name="hand_white">
        <color rgba="0.913725 0.913725 0.847059 1"/>
      </material>
    </visual>
    <collision>
      <origin rpy="0 0 0" xyz="0 0 0"/>
      <geometry>
        <mesh filename="../meshes/visual/f41.STL"/>
      </geometry>
    </collision>
  </link>
  <joint name="hand_left_f41_joint" type="revolute">
    <origin rpy="1.5708 0.034907 1.5708" xyz="-0.021466 0.034458 0.032384"/>
    <parent link="hand_left_palm"/>
    <child link="hand_left_f41"/>
    <axis xyz="0 0 1"/>
    <limit effort="10" lower="-0.4" upper="0.4" velocity="3.14"/>
    <dynamics damping="1.0" friction="0.01"/>
  </joint>
  <link name="hand_left_f42">
    <inertial>
      <origin rpy="0 0 0" xyz="0.021044 0.0035949 -7.944E-05"/>
      <mass value="0.0096409"/>
      <inertia ixx="3.5E-07" ixy="-3E-08" ixz="0" iyy="1.24E-06" iyz="0" izz="1.35E-06"/>
    </inertial>
    <visual>
      <origin rpy="0 0 0" xyz="0 0 0"/>
      <geometry>
        <mesh filename="../meshes/visual/f42.STL"/>
      </geometry>
      <material name="hand_white">
        <color rgba="0.913725 0.913725 0.847059 1"/>
      </material>
    </visual>
    <collision>
      <origin rpy="0 0 0" xyz="0 0 0"/>
      <geometry>
        <mesh filename="../meshes/visual/f42.STL"/>
      </geometry>
    </collision>
  </link>
  <joint name="hand_left_f42_joint" type="revolute">
    <origin rpy="1.5708 0 1.5708" xyz="0 0 0"/>
    <parent link="hand_left_f41"/>
    <child link="hand_left_f42"/>
    <axis xyz="0 0 1"/>
    <limit effort="10" lower="0" upper="1.6" velocity="3.14"/>
    <dynamics damping="1.0" friction="0.01"/>
  </joint>
  <link name="hand_left_f43">
    <inertial>
      <origin rpy="0 0 0" xyz="0.010032 -0.00058707 -9.093E-05"/>
      <mass value="0.0071009"/>
      <inertia ixx="2.8E-07" ixy="-8E-08" ixz="0" iyy="6.9E-07" iyz="0" izz="7E-07"/>
    </inertial>
    <visual>
      <origin rpy="0 0 0" xyz="0 0 0"/>
      <geometry>
        <mesh filename="../meshes/visual/f43.STL"/>
      </geometry>
      <material name="hand_white">
        <color rgba="0.913725 0.913725 0.847059 1"/>
      </material>
    </visual>
    <collision>
      <origin rpy="0 0 0" xyz="0 0 0"/>
      <geometry>
        <mesh filename="../meshes/visual/f43.STL"/>
      </geometry>
    </collision>
  </link>
  <joint name="hand_left_f43_joint" type="revolute">
    <origin rpy="0 0 0" xyz="0.035975 0.001338 0"/>
    <parent link="hand_left_f42"/>
    <child link="hand_left_f43"/>
    <axis xyz="0 0 1"/>
    <limit effort="10" lower="0" upper="1.744" velocity="3.14"/>
    <dynamics damping="1.0" friction="0.01"/>
  </joint>
  <link name="hand_left_f44">
    <inertial>
      <origin rpy="0 0 0" xyz="0.010482 -0.0030354 -1.03E-05"/>
      <mass value="0.0049513"/>
      <inertia ixx="1.3E-07" ixy="-6E-08" ixz="0" iyy="3.2E-07" iyz="0" izz="3.7E-07"/>
    </inertial>
    <visual>
      <origin rpy="0 0 0" xyz="0 0 0"/>
      <geometry>
        <mesh filename="../meshes/visual/f44.STL"/>
      </geometry>
      <material name="hand_white">
        <color rgba="0.913725 0.913725 0.847059 1"/>
      </material>
    </visual>
    <collision>
      <origin rpy="0 0 0" xyz="0 0 0"/>
      <geometry>
        <mesh filename="../meshes/visual/f44.STL"/>
      </geometry>
    </collision>
  </link>
  <joint name="hand_left_f44_joint" type="revolute">
    <origin rpy="0 0 0" xyz="0.024621 -0.004339 0"/>
    <parent link="hand_left_f43"/>
    <child link="hand_left_f44"/>
    <axis xyz="0 0 1"/>
    <limit effort="10" lower="0" upper="1.744" velocity="3.14"/>
    <dynamics damping="1.0" friction="0.01"/>
  </joint>
  <link name="hand_left_f44_end">
        </link>
  <joint name="hand_left_f44_end_joint" type="fixed">
    <origin rpy="0 0 0" xyz="0.021123 0.0013734 0"/>
    <parent link="hand_left_f44"/>
    <child link="hand_left_f44_end"/>
    <axis xyz="0 0 0"/>
  </joint>
  <link name="hand_left_f51">
    <inertial>
      <origin rpy="0 0 0" xyz="0.0053991 0.0016936 0.01157"/>
      <mass value="0.022542"/>
      <inertia ixx="3.06E-06" ixy="4.2E-07" ixz="3.3E-07" iyy="5.17E-06" iyz="1E-08" izz="3.39E-06"/>
    </inertial>
    <visual>
      <origin rpy="0 0 0" xyz="0 0 0"/>
      <geometry>
        <mesh filename="../meshes/visual/f51.STL" scale="-1 1 1"/>
      </geometry>
      <material name="hand_white">
        <color rgba="0.913725 0.913725 0.847059 1"/>
      </material>
    </visual>
    <collision>
      <origin rpy="0 0 0" xyz="0 0 0"/>
      <geometry>
        <mesh filename="../meshes/visual/f51.STL" scale="-1 1 1"/>
      </geometry>
    </collision>
  </link>
  <joint name="hand_left_f51_joint" type="revolute">
    <origin rpy="0 0 3.14" xyz="-0.00049657 -0.0084524 -0.066754"/>
    <parent link="hand_left_palm"/>
    <child link="hand_left_f51"/>
    <axis xyz="0 0 1"/>
    <limit effort="10" lower="0" upper="1.9" velocity="3.14"/>
    <dynamics damping="1.0" friction="0.01"/>
  </joint>
  <link name="hand_left_f52">
    <inertial>
      <origin rpy="0 0 0" xyz="0.03317 -0.0064258 -0.00083733"/>
      <mass value="0.12909"/>
      <inertia ixx="1.628E-05" ixy="-6.22E-06" ixz="-3.01E-06" iyy="6.413E-05" iyz="1.13E-06" izz="6.867E-05"/>
    </inertial>
    <visual>
      <origin rpy="0 0 0" xyz="0 0 0"/>
      <geometry>
        <mesh filename="../meshes/visual/f52.STL" scale="1 1 -1"/>
      </geometry>
      <material name="hand_white">
        <color rgba="0.913725 0.913725 0.847059 1"/>
      </material>
    </visual>
    <collision>
      <origin rpy="0 0 0" xyz="0 0 0"/>
      <geometry>
        <mesh filename="../meshes/visual/f52.STL" scale="1 1 -1"/>
      </geometry>
    </collision>
  </link>
  <joint name="hand_left_f52_joint" type="revolute">
    <origin rpy="1.2969 -0.25085 1.4244" xyz="-0.0092399 0.0031582 0.022073"/>
    <parent link="hand_left_f51"/>
    <child link="hand_left_f52"/>
    <axis xyz="0 0 1"/>
    <limit effort="10" lower="0" upper="1.332" velocity="3.14"/>
    <dynamics damping="1.0" friction="0.01"/>
  </joint>
  <link name="hand_left_f53">
    <inertial>
      <origin rpy="0 0 0" xyz="0.021453 0.0041043 -5.93E-06"/>
      <mass value="0.011849"/>
      <inertia ixx="6.6E-07" ixy="-1E-08" ixz="-1E-08" iyy="1.94E-06" iyz="0" izz="1.88E-06"/>
    </inertial>
    <visual>
      <origin rpy="0 0 0" xyz="0 0 0"/>
      <geometry>
        <mesh filename="../meshes/visual/f53.STL"/>
      </geometry>
      <material name="hand_white">
        <color rgba="0.913725 0.913725 0.847059 1"/>
      </material>
    </visual>
    <collision>
      <origin rpy="0 0 0" xyz="0 0 0"/>
      <geometry>
        <mesh filename="../meshes/visual/f53.STL"/>
      </geometry>
    </collision>
  </link>
  <joint name="hand_left_f53_joint" type="revolute">
    <origin rpy="0 0 0" xyz="0.0654 0 0"/>
    <parent link="hand_left_f52"/>
    <child link="hand_left_f53"/>
    <axis xyz="0 0 1"/>
    <limit effort="10" lower="0" upper="1.744" velocity="3.14"/>
    <dynamics damping="1.0" friction="0.01"/>
  </joint>
  <link name="hand_left_f54">
    <inertial>
      <origin rpy="0 0 0" xyz="0.013824 -0.0017677 -5.567E-05"/>
      <mass value="0.010348"/>
      <inertia ixx="5.5E-07" ixy="-1.5E-07" ixz="0" iyy="1.35E-06" iyz="0" izz="1.17E-06"/>
    </inertial>
    <visual>
      <origin rpy="0 0 0" xyz="0 0 0"/>
      <geometry>
        <mesh filename="../meshes/visual/f54.STL"/>
      </geometry>
      <material name="hand_white">
        <color rgba="0.913725 0.913725 0.847059 1"/>
      </material>
    </visual>
    <collision>
      <origin rpy="0 0 0" xyz="0 0 0"/>
      <geometry>
        <mesh filename="../meshes/visual/f54.STL"/>
      </geometry>
    </collision>
  </link>
  <joint name="hand_left_f54_joint" type="revolute">
    <origin rpy="0 0 0" xyz="0.035837 0.0034221 0"/>
    <parent link="hand_left_f53"/>
    <child link="hand_left_f54"/>
    <axis xyz="0 0 1"/>
    <limit effort="10" lower="0" upper="1.744" velocity="3.14"/>
    <dynamics damping="1.0" friction="0.01"/>
  </joint>
  <link name="hand_left_f54_end">
        </link>
  <joint name="hand_left_f54_end_joint" type="fixed">
    <origin rpy="0 0 0" xyz="0.024 0.0044004 0"/>
    <parent link="hand_left_f54"/>
    <child link="hand_left_f54_end"/>
    <axis xyz="0 0 0"/>
  </joint>
  <link name="hand_left_wrist">
        </link>
  <joint name="hand_left_wrist_joint" type="fixed">
    <origin rpy="1.570796326 0.0 1.570796326" xyz="-0.025962 -0.005739 -0.069754"/>
    <parent link="hand_left_palm"/>
    <child link="hand_left_wrist"/>
  </joint>
</robot>
